[2023-07-09T16:47:22.424+0000] {taskinstance.py:1087} INFO - Dependencies all met for <TaskInstance: my_daily_dag.create_rds_table manual__2023-07-09T05:10:21.252598+00:00 [queued]>
[2023-07-09T16:47:22.449+0000] {taskinstance.py:1087} INFO - Dependencies all met for <TaskInstance: my_daily_dag.create_rds_table manual__2023-07-09T05:10:21.252598+00:00 [queued]>
[2023-07-09T16:47:22.449+0000] {taskinstance.py:1283} INFO - 
--------------------------------------------------------------------------------
[2023-07-09T16:47:22.449+0000] {taskinstance.py:1284} INFO - Starting attempt 1 of 4
[2023-07-09T16:47:22.449+0000] {taskinstance.py:1285} INFO - 
--------------------------------------------------------------------------------
[2023-07-09T16:47:22.469+0000] {taskinstance.py:1304} INFO - Executing <Task(PythonOperator): create_rds_table> on 2023-07-09 05:10:21.252598+00:00
[2023-07-09T16:47:22.477+0000] {standard_task_runner.py:55} INFO - Started process 3669 to run task
[2023-07-09T16:47:22.485+0000] {standard_task_runner.py:82} INFO - Running: ['***', 'tasks', 'run', 'my_daily_dag', 'create_rds_table', 'manual__2023-07-09T05:10:21.252598+00:00', '--job-id', '13', '--raw', '--subdir', 'DAGS_FOLDER/first_dag.py', '--cfg-path', '/tmp/tmp1mw5jj5t']
[2023-07-09T16:47:22.488+0000] {standard_task_runner.py:83} INFO - Job 13: Subtask create_rds_table
[2023-07-09T16:47:22.698+0000] {task_command.py:389} INFO - Running <TaskInstance: my_daily_dag.create_rds_table manual__2023-07-09T05:10:21.252598+00:00 [running]> on host ip-172-31-34-219.ap-southeast-2.compute.internal
[2023-07-09T16:47:22.894+0000] {taskinstance.py:1511} INFO - Exporting the following env vars:
AIRFLOW_CTX_DAG_OWNER=***
AIRFLOW_CTX_DAG_ID=my_daily_dag
AIRFLOW_CTX_TASK_ID=create_rds_table
AIRFLOW_CTX_EXECUTION_DATE=2023-07-09T05:10:21.252598+00:00
AIRFLOW_CTX_TRY_NUMBER=1
AIRFLOW_CTX_DAG_RUN_ID=manual__2023-07-09T05:10:21.252598+00:00
[2023-07-09T16:47:22.896+0000] {taskinstance.py:1772} ERROR - Task failed with exception
Traceback (most recent call last):
  File "/home/ubuntu/venv/lib/python3.10/site-packages/airflow/operators/python.py", line 175, in execute
    return_value = self.execute_callable()
  File "/home/ubuntu/venv/lib/python3.10/site-packages/airflow/operators/python.py", line 192, in execute_callable
    return self.python_callable(*self.op_args, **self.op_kwargs)
  File "/home/ubuntu/airflow/dags/first_dag.py", line 50, in create_rds_table
    cursor = conn.cursor()
NameError: name 'conn' is not defined
[2023-07-09T16:47:22.939+0000] {taskinstance.py:1322} INFO - Marking task as UP_FOR_RETRY. dag_id=my_daily_dag, task_id=create_rds_table, execution_date=20230709T051021, start_date=20230709T164722, end_date=20230709T164722
[2023-07-09T16:47:22.961+0000] {standard_task_runner.py:100} ERROR - Failed to execute job 13 for task create_rds_table (name 'conn' is not defined; 3669)
[2023-07-09T16:47:22.981+0000] {local_task_job.py:159} INFO - Task exited with return code 1
[2023-07-09T16:47:23.036+0000] {taskinstance.py:2582} INFO - 0 downstream tasks scheduled from follow-on schedule check
