[2023-07-09T17:05:58.254+0000] {taskinstance.py:1087} INFO - Dependencies all met for <TaskInstance: my_daily_dag.create_rds_table manual__2023-07-09T05:10:21.252598+00:00 [queued]>
[2023-07-09T17:05:58.328+0000] {taskinstance.py:1087} INFO - Dependencies all met for <TaskInstance: my_daily_dag.create_rds_table manual__2023-07-09T05:10:21.252598+00:00 [queued]>
[2023-07-09T17:05:58.328+0000] {taskinstance.py:1283} INFO - 
--------------------------------------------------------------------------------
[2023-07-09T17:05:58.328+0000] {taskinstance.py:1284} INFO - Starting attempt 4 of 4
[2023-07-09T17:05:58.328+0000] {taskinstance.py:1285} INFO - 
--------------------------------------------------------------------------------
[2023-07-09T17:05:58.410+0000] {taskinstance.py:1304} INFO - Executing <Task(PythonOperator): create_rds_table> on 2023-07-09 05:10:21.252598+00:00
[2023-07-09T17:05:58.448+0000] {standard_task_runner.py:55} INFO - Started process 11037 to run task
[2023-07-09T17:05:58.474+0000] {standard_task_runner.py:82} INFO - Running: ['***', 'tasks', 'run', 'my_daily_dag', 'create_rds_table', 'manual__2023-07-09T05:10:21.252598+00:00', '--job-id', '31', '--raw', '--subdir', 'DAGS_FOLDER/first_dag.py', '--cfg-path', '/tmp/tmpbi0sb3eo']
[2023-07-09T17:05:58.498+0000] {standard_task_runner.py:83} INFO - Job 31: Subtask create_rds_table
[2023-07-09T17:05:59.330+0000] {task_command.py:389} INFO - Running <TaskInstance: my_daily_dag.create_rds_table manual__2023-07-09T05:10:21.252598+00:00 [running]> on host ip-172-31-34-219.ap-southeast-2.compute.internal
[2023-07-09T17:06:00.159+0000] {taskinstance.py:1511} INFO - Exporting the following env vars:
AIRFLOW_CTX_DAG_OWNER=***
AIRFLOW_CTX_DAG_ID=my_daily_dag
AIRFLOW_CTX_TASK_ID=create_rds_table
AIRFLOW_CTX_EXECUTION_DATE=2023-07-09T05:10:21.252598+00:00
AIRFLOW_CTX_TRY_NUMBER=4
AIRFLOW_CTX_DAG_RUN_ID=manual__2023-07-09T05:10:21.252598+00:00
[2023-07-09T17:06:00.333+0000] {taskinstance.py:1772} ERROR - Task failed with exception
Traceback (most recent call last):
  File "/home/ubuntu/venv/lib/python3.10/site-packages/airflow/operators/python.py", line 175, in execute
    return_value = self.execute_callable()
  File "/home/ubuntu/venv/lib/python3.10/site-packages/airflow/operators/python.py", line 192, in execute_callable
    return self.python_callable(*self.op_args, **self.op_kwargs)
  File "/home/ubuntu/airflow/dags/first_dag.py", line 51, in create_rds_table
    cursor = conn.cursor()
AttributeError: 'NoneType' object has no attribute 'cursor'
[2023-07-09T17:06:00.479+0000] {taskinstance.py:1322} INFO - Marking task as FAILED. dag_id=my_daily_dag, task_id=create_rds_table, execution_date=20230709T051021, start_date=20230709T170558, end_date=20230709T170600
[2023-07-09T17:06:00.575+0000] {standard_task_runner.py:100} ERROR - Failed to execute job 31 for task create_rds_table ('NoneType' object has no attribute 'cursor'; 11037)
[2023-07-09T17:06:00.632+0000] {local_task_job.py:159} INFO - Task exited with return code 1
[2023-07-09T17:06:00.754+0000] {taskinstance.py:2582} INFO - 0 downstream tasks scheduled from follow-on schedule check
