[2023-07-09T17:09:25.643+0000] {taskinstance.py:1087} INFO - Dependencies all met for <TaskInstance: my_daily_dag.create_rds_table manual__2023-07-09T17:09:22.086687+00:00 [queued]>
[2023-07-09T17:09:25.653+0000] {taskinstance.py:1087} INFO - Dependencies all met for <TaskInstance: my_daily_dag.create_rds_table manual__2023-07-09T17:09:22.086687+00:00 [queued]>
[2023-07-09T17:09:25.653+0000] {taskinstance.py:1283} INFO - 
--------------------------------------------------------------------------------
[2023-07-09T17:09:25.653+0000] {taskinstance.py:1284} INFO - Starting attempt 1 of 4
[2023-07-09T17:09:25.653+0000] {taskinstance.py:1285} INFO - 
--------------------------------------------------------------------------------
[2023-07-09T17:09:25.664+0000] {taskinstance.py:1304} INFO - Executing <Task(PythonOperator): create_rds_table> on 2023-07-09 17:09:22.086687+00:00
[2023-07-09T17:09:25.672+0000] {standard_task_runner.py:55} INFO - Started process 12963 to run task
[2023-07-09T17:09:25.684+0000] {standard_task_runner.py:82} INFO - Running: ['***', 'tasks', 'run', 'my_daily_dag', 'create_rds_table', 'manual__2023-07-09T17:09:22.086687+00:00', '--job-id', '42', '--raw', '--subdir', 'DAGS_FOLDER/first_dag.py', '--cfg-path', '/tmp/tmprg7st01o']
[2023-07-09T17:09:25.687+0000] {standard_task_runner.py:83} INFO - Job 42: Subtask create_rds_table
[2023-07-09T17:09:25.829+0000] {task_command.py:389} INFO - Running <TaskInstance: my_daily_dag.create_rds_table manual__2023-07-09T17:09:22.086687+00:00 [running]> on host ip-172-31-34-219.ap-southeast-2.compute.internal
[2023-07-09T17:09:26.032+0000] {taskinstance.py:1511} INFO - Exporting the following env vars:
AIRFLOW_CTX_DAG_OWNER=***
AIRFLOW_CTX_DAG_ID=my_daily_dag
AIRFLOW_CTX_TASK_ID=create_rds_table
AIRFLOW_CTX_EXECUTION_DATE=2023-07-09T17:09:22.086687+00:00
AIRFLOW_CTX_TRY_NUMBER=1
AIRFLOW_CTX_DAG_RUN_ID=manual__2023-07-09T17:09:22.086687+00:00
[2023-07-09T17:09:26.064+0000] {taskinstance.py:1772} ERROR - Task failed with exception
Traceback (most recent call last):
  File "/home/ubuntu/venv/lib/python3.10/site-packages/airflow/operators/python.py", line 175, in execute
    return_value = self.execute_callable()
  File "/home/ubuntu/venv/lib/python3.10/site-packages/airflow/operators/python.py", line 192, in execute_callable
    return self.python_callable(*self.op_args, **self.op_kwargs)
  File "/home/ubuntu/airflow/dags/first_dag.py", line 50, in create_rds_table
    cursor = conn.cursor()
AttributeError: 'NoneType' object has no attribute 'cursor'
[2023-07-09T17:09:26.086+0000] {taskinstance.py:1322} INFO - Marking task as UP_FOR_RETRY. dag_id=my_daily_dag, task_id=create_rds_table, execution_date=20230709T170922, start_date=20230709T170925, end_date=20230709T170926
[2023-07-09T17:09:26.099+0000] {standard_task_runner.py:100} ERROR - Failed to execute job 42 for task create_rds_table ('NoneType' object has no attribute 'cursor'; 12963)
[2023-07-09T17:09:26.139+0000] {local_task_job.py:159} INFO - Task exited with return code 1
[2023-07-09T17:09:26.178+0000] {taskinstance.py:2582} INFO - 0 downstream tasks scheduled from follow-on schedule check
