[2023-07-10T04:34:20.981+0000] {taskinstance.py:1087} INFO - Dependencies all met for <TaskInstance: my_daily_dag.connect_to_rds scheduled__2023-07-09T00:00:00+00:00 [queued]>
[2023-07-10T04:34:21.100+0000] {taskinstance.py:1087} INFO - Dependencies all met for <TaskInstance: my_daily_dag.connect_to_rds scheduled__2023-07-09T00:00:00+00:00 [queued]>
[2023-07-10T04:34:21.100+0000] {taskinstance.py:1283} INFO - 
--------------------------------------------------------------------------------
[2023-07-10T04:34:21.100+0000] {taskinstance.py:1284} INFO - Starting attempt 1 of 4
[2023-07-10T04:34:21.100+0000] {taskinstance.py:1285} INFO - 
--------------------------------------------------------------------------------
[2023-07-10T04:34:21.226+0000] {taskinstance.py:1304} INFO - Executing <Task(PythonOperator): connect_to_rds> on 2023-07-09 00:00:00+00:00
[2023-07-10T04:34:21.284+0000] {standard_task_runner.py:55} INFO - Started process 1412 to run task
[2023-07-10T04:34:21.272+0000] {standard_task_runner.py:82} INFO - Running: ['***', 'tasks', 'run', 'my_daily_dag', 'connect_to_rds', 'scheduled__2023-07-09T00:00:00+00:00', '--job-id', '50', '--raw', '--subdir', 'DAGS_FOLDER/first_dag.py', '--cfg-path', '/tmp/tmp79wo6ars']
[2023-07-10T04:34:21.357+0000] {standard_task_runner.py:83} INFO - Job 50: Subtask connect_to_rds
[2023-07-10T04:34:22.257+0000] {task_command.py:389} INFO - Running <TaskInstance: my_daily_dag.connect_to_rds scheduled__2023-07-09T00:00:00+00:00 [running]> on host ip-172-31-34-219.ap-southeast-2.compute.internal
[2023-07-10T04:34:23.019+0000] {taskinstance.py:1511} INFO - Exporting the following env vars:
AIRFLOW_CTX_DAG_OWNER=***
AIRFLOW_CTX_DAG_ID=my_daily_dag
AIRFLOW_CTX_TASK_ID=connect_to_rds
AIRFLOW_CTX_EXECUTION_DATE=2023-07-09T00:00:00+00:00
AIRFLOW_CTX_TRY_NUMBER=1
AIRFLOW_CTX_DAG_RUN_ID=scheduled__2023-07-09T00:00:00+00:00
[2023-07-10T04:34:23.174+0000] {logging_mixin.py:137} INFO - Connection to the database successful!
[2023-07-10T04:34:23.326+0000] {taskinstance.py:1772} ERROR - Task failed with exception
Traceback (most recent call last):
  File "/home/ubuntu/venv/lib/python3.10/site-packages/airflow/operators/python.py", line 175, in execute
    return_value = self.execute_callable()
  File "/home/ubuntu/venv/lib/python3.10/site-packages/airflow/operators/python.py", line 192, in execute_callable
    return self.python_callable(*self.op_args, **self.op_kwargs)
  File "/home/ubuntu/airflow/dags/first_dag.py", line 43, in connect_to_rds
    context['ti'].xcom_push(key='conn', value=conn)
  File "/home/ubuntu/venv/lib/python3.10/site-packages/airflow/utils/session.py", line 75, in wrapper
    return func(*args, session=session, **kwargs)
  File "/home/ubuntu/venv/lib/python3.10/site-packages/airflow/models/taskinstance.py", line 2294, in xcom_push
    XCom.set(
  File "/home/ubuntu/venv/lib/python3.10/site-packages/airflow/utils/session.py", line 72, in wrapper
    return func(*args, **kwargs)
  File "/home/ubuntu/venv/lib/python3.10/site-packages/airflow/models/xcom.py", line 234, in set
    value = cls.serialize_value(
  File "/home/ubuntu/venv/lib/python3.10/site-packages/airflow/models/xcom.py", line 627, in serialize_value
    return json.dumps(value, cls=XComEncoder).encode("UTF-8")
  File "/usr/lib/python3.10/json/__init__.py", line 238, in dumps
    **kw).encode(obj)
  File "/home/ubuntu/venv/lib/python3.10/site-packages/airflow/utils/json.py", line 176, in encode
    return super().encode(o)
  File "/usr/lib/python3.10/json/encoder.py", line 199, in encode
    chunks = self.iterencode(o, _one_shot=True)
  File "/usr/lib/python3.10/json/encoder.py", line 257, in iterencode
    return _iterencode(o, 0)
  File "/home/ubuntu/venv/lib/python3.10/site-packages/airflow/utils/json.py", line 153, in default
    CLASSNAME: o.__module__ + "." + o.__class__.__qualname__,
AttributeError: 'psycopg2.extensions.connection' object has no attribute '__module__'. Did you mean: '__reduce__'?
[2023-07-10T04:34:23.374+0000] {taskinstance.py:1322} INFO - Marking task as UP_FOR_RETRY. dag_id=my_daily_dag, task_id=connect_to_rds, execution_date=20230709T000000, start_date=20230710T043421, end_date=20230710T043423
[2023-07-10T04:34:23.421+0000] {standard_task_runner.py:100} ERROR - Failed to execute job 50 for task connect_to_rds ('psycopg2.extensions.connection' object has no attribute '__module__'; 1412)
[2023-07-10T04:34:23.461+0000] {local_task_job.py:159} INFO - Task exited with return code 1
[2023-07-10T04:34:23.757+0000] {taskinstance.py:2582} INFO - 0 downstream tasks scheduled from follow-on schedule check
