[2023-07-20T20:21:27.290+0000] {taskinstance.py:1087} INFO - Dependencies all met for <TaskInstance: real_estate_etl_dag.load_task scheduled__2023-07-19T20:05:06.697330+00:00 [queued]>
[2023-07-20T20:21:27.298+0000] {taskinstance.py:1087} INFO - Dependencies all met for <TaskInstance: real_estate_etl_dag.load_task scheduled__2023-07-19T20:05:06.697330+00:00 [queued]>
[2023-07-20T20:21:27.298+0000] {taskinstance.py:1283} INFO - 
--------------------------------------------------------------------------------
[2023-07-20T20:21:27.298+0000] {taskinstance.py:1284} INFO - Starting attempt 4 of 4
[2023-07-20T20:21:27.298+0000] {taskinstance.py:1285} INFO - 
--------------------------------------------------------------------------------
[2023-07-20T20:21:27.310+0000] {taskinstance.py:1304} INFO - Executing <Task(PythonOperator): load_task> on 2023-07-19 20:05:06.697330+00:00
[2023-07-20T20:21:27.318+0000] {standard_task_runner.py:55} INFO - Started process 614007 to run task
[2023-07-20T20:21:27.322+0000] {standard_task_runner.py:82} INFO - Running: ['***', 'tasks', 'run', 'real_estate_etl_dag', 'load_task', 'scheduled__2023-07-19T20:05:06.697330+00:00', '--job-id', '169', '--raw', '--subdir', 'DAGS_FOLDER/real_estate_etl_dag.py', '--cfg-path', '/tmp/tmpl9e1wc3f']
[2023-07-20T20:21:27.325+0000] {standard_task_runner.py:83} INFO - Job 169: Subtask load_task
[2023-07-20T20:21:27.443+0000] {task_command.py:389} INFO - Running <TaskInstance: real_estate_etl_dag.load_task scheduled__2023-07-19T20:05:06.697330+00:00 [running]> on host ip-172-31-34-219.ap-southeast-2.compute.internal
[2023-07-20T20:21:27.553+0000] {taskinstance.py:1511} INFO - Exporting the following env vars:
AIRFLOW_CTX_DAG_OWNER=***
AIRFLOW_CTX_DAG_ID=real_estate_etl_dag
AIRFLOW_CTX_TASK_ID=load_task
AIRFLOW_CTX_EXECUTION_DATE=2023-07-19T20:05:06.697330+00:00
AIRFLOW_CTX_TRY_NUMBER=4
AIRFLOW_CTX_DAG_RUN_ID=scheduled__2023-07-19T20:05:06.697330+00:00
[2023-07-20T20:21:27.569+0000] {logging_mixin.py:137} INFO - Error connecting to the database: connection to server at "real-estate-db.czvpezojzuuw.ap-southeast-2.rds.amazonaws.com" (172.31.48.42), port 5432 failed: fe_sendauth: no password supplied
[2023-07-20T20:21:27.570+0000] {taskinstance.py:1772} ERROR - Task failed with exception
Traceback (most recent call last):
  File "/home/ubuntu/venv/lib/python3.10/site-packages/airflow/operators/python.py", line 175, in execute
    return_value = self.execute_callable()
  File "/home/ubuntu/venv/lib/python3.10/site-packages/airflow/operators/python.py", line 192, in execute_callable
    return self.python_callable(*self.op_args, **self.op_kwargs)
  File "/home/ubuntu/airflow/dags/real_estate_etl_dag.py", line 107, in load_to_rds
    cursor = conn.cursor()
UnboundLocalError: local variable 'conn' referenced before assignment
[2023-07-20T20:21:27.590+0000] {taskinstance.py:1322} INFO - Marking task as FAILED. dag_id=real_estate_etl_dag, task_id=load_task, execution_date=20230719T200506, start_date=20230720T202127, end_date=20230720T202127
[2023-07-20T20:21:27.602+0000] {standard_task_runner.py:100} ERROR - Failed to execute job 169 for task load_task (local variable 'conn' referenced before assignment; 614007)
[2023-07-20T20:21:27.617+0000] {local_task_job.py:159} INFO - Task exited with return code 1
[2023-07-20T20:21:27.662+0000] {taskinstance.py:2582} INFO - 0 downstream tasks scheduled from follow-on schedule check
